Workbook

Sheet BBDD
A1: DIA SEG | B1: MES SEG | C1: SEMANA | D1: QUIEBRE | E1: ATRIBUIBLE | F1: REINGRESO | G1: SUPERVISOR | H1: LINEA | I1: ESTADO | J1: TERMINADA | K1: ANULADA | L1: PENDIENTE | M1: AGENDADAS | N1: PENDIENTES | O1: SUSPENDIDAS | P1: ESTADO AGENDA | Q1: FECHA AGENDA | R1: FRANJA AGENDA | S1: DIA AGENDA | T1: MES AGENDA | U1: MOTIVO DE SUSPENSION | V1: CEDULA CLIENTE | W1: TELEFONO CLIENTE | X1: LEGALIZADA | Y1: PEND LEGALIZAR | Z1: ESTADO LEG | AA1: DIF DIAS | AB1: FECHA LEG | AC1: FINAL Vs LG | AD1: % PAGO | AE1: DIA PDC | AF1: DIAS MES PDC | AG1: EMPAQUETADAS | AH1: META | AI1: BA | AJ1: DUO | AK1: TRIO | AL1: SubPeticionTramitadorCD | AM1: CanalRegistroPeticionID | AN1: SubPeticionID | AO1: Num_Subpeticion_Atis | AP1: FechaRegistroPeticion | AQ1: FuerzaVentaID | AR1: Telefono | AS1: ProductoID | AT1: PlanContratadoID | AU1: PlanID | AV1: DireccionID | AW1: OperacionComercialProductoID | AX1: Nom_OC | AY1: ClienteID | AZ1: Anio_Seg | BA1: Mes_Seg | BB1: Dia_Seg | BC1: TipoOperacionPeticionID | BD1: Tipo_Operacion_Peticion | BE1: PeticionID | BF1: ID_Peticion | BG1: Nom_PS | BH1: ProductoPlanCD | BI1: Num_Agrupacion_Pet_Atis | BJ1: AgrupacionPeticionID | BK1: CuentaFacturacionID | BL1: SuscripcionID | BM1: Variable | BN1: Nom_Segmento_Cuenta | BO1: ID_Cuenta | BP1: SubSegmentoCuentaDesc | BQ1: Anio_Reg | BR1: Mes_Reg | BS1: Dia_Reg | BT1: FechaIniEstPetAtis | BU1: EstadoPetAtis | BV1: FechaIniEstadoSubPetAtis | BW1: EstadoSubPetAtis | BX1: FechaIngresoAtiempo | BY1: FechaIniEstadoAtiempo | BZ1: EstadoAtiempo | CA1: Localidad | CB1: Depto | CC1: Direccion | CD1: Nom_Barrio_PC | CE1: BarrioID | CF1: Cod_Dane | CG1: Distrito | CH1: Cluster1 | CI1: Cedula_Vendedor_Atis | CJ1: Nom_Fuerza_Venta | CK1: Canal | CL1: SubCanal | CM1: Unidad_Fuerza_de_Ventas | CN1: Nom_Punto_Venta | CO1: Nom_Canal_Venta | CP1: ID_Canal_Venta | CQ1: TipoFuerzaVentaCD | CR1: TipoFuerzaVentaDesc | CS1: Nom_Tipo_Uso | CT1: Estrato | CU1: MX_Hom | CV1: ProductoDesc | CW1: Nom_Plan_Tarifario | CX1: Nom_PS_Equipo | CY1: Nom_Ult_Quiebre_Atmp | CZ1: TipoQuiebreDesc | DA1: Nom_Usuario_Ult_Actividad | DB1: ActividadPeticionID | DC1: Fec_Ini_Ult_Actividad | DD1: Fec_Est_Ult_Actividad | DE1: Desc_Est_Ult_Actividad | DF1: Variable_Hom | DG1: DireccionElectronica | DH1: Correo_Valido | DI1: DSLAM | DJ1: Velocidad | DK1: TenenciaCliente | DL1: Tipo_Cliente | DM1: Paquete | DN1: Producto | DO1: MX_Configurado | DP1: distribuidor | DQ1: proy_soc | DR1: Tramitador_UsuAtis | DS1: Tramitador_Nom | DT1: Cedula_Tramitador | DU1: Flag_Recibido_ATiempo | DV1: Total_Homol | DW1: Regional | DX1: CuentaPadre | DY1: TipoEnvio | DZ1: CaracteristicaEquipo | EA1: TVHD | EB1: Reingreso2 | EC1: Bianual3 | ED1: FechaSeguimiento | EE1: Zona | EF1: CicloFacturacion | EG1: DocInterlocutor | EH1: NombreInterlocutor | EI1: FechaAltaFactElect | EJ1: CorreoFactElect | EK1: DocumentoFventaFactElect | EL1: UsuarioCdFactElect | EM1: NombreVendFactElect | EN1: UnidadFactElect | EO1: ActivacionFactElect | EP1: NitUnidadFuerzaventa | EQ1: NombreProfesional | ER1: CedulaProfesional | ES1: PlanExpansion | ET1: BAEstratoSup | EU1: CodPlanDcto | EV1: NomPlanDcto | EW1: SegmentoCliente | EX1: SubsegmentoCliente | EY1: FlagTvAzteca | EZ1: ZonaBA | FA1: Canal_Hom | FB1: Dpto_Hom | FC1: Estado_Hom | FD1: Dpto_Nom | FE1: Mun_Nom | FF1: Loc_Nom | FG1: Producto_Hom | FH1: Plan_Hom | FI1: Portafolio | FJ1: SubCanal_Hom | FK1: Unidad_Fuerza_de_Ventas_Hom | FL1: DistArmCaja | FM1: FlagCyC | FN1: NombrePunto | FO1: CodigoPunto | FP1: Tarifa_full | FQ1: Tarifa_sin_SubsContr | FR1: TarifaMXFinal | FS1: CodDaneEmpresas | FT1: LocalidadEmpresas | FU1: DepartamentoEmpresas | FV1: RegionalEmpresas | FW1: MarcaTrioMV | FX1: CodigoCliente | FY1: AplicacionRespetoiVentas | FZ1: FlagOfertaPRO | GA1: MarcaTrioHD | GB1: FTTH | GC1: TenenciaPlanta | GD1: PlanLB | GE1: TarifaFullLB | GF1: TarifaMXLB | GG1: PlanBA | GH1: TarifaFullBA | GI1: TarifaMXBA | GJ1: PlanTV | GK1: TarifaFullTV | GL1: TarifaMXTV | GM1: Tarifa_MXFinal | GN1: Tarifa_MXInicial | GO1: DeltaMX | GP1: FlagEnvioCampana | GQ1: SVATV2833 | GR1: SVABA2864 | GS1: Empresa | GT1: fec_comercializacion_cto | GU1: Canal_Acceso | GV1: Autenticacion_Correo | GW1: Convergente | GX1: MacroTenenciaIni | GY1: MacroTenenciaFin | GZ1: Tipo_Convergente | HA1: Coinversion | HB1: poligono_kkr | HC1: comuna_kkr | HD1: region_kkr | HE1: Segmento_Homologado | HF1: Id_Tiles | HG1: Alta_mismo_mes_MTotal | HH1: CC_Pospago_MTotal | HI1: Fuente_Pospago_MTotal | HJ1: fecha_registro_movil_MTotal | HK1: Nom_Agente_Movil_MTotal | HL1: Canal_Movil_MTotal | HM1: id_punto_Mov_MTotal | HN1: nom_punto_Mov_MTotal | HO1: nom_vendedor_Mov_MTotal | HP1: NumIdentVendedor_Mov_MTotal | HQ1: NBA | HR1: Tipo_Venta | HS1: Flag_TAT | HT1: cod_tienda | HU1: canal_fibra | HV1: Valor_Vision_Cliente | HW1: Oferta_Empaquetada | HX1: OF_Empaquetada_Movil | HY1: TarifaMXFinalEMPAQ | HZ1: TarifaMXFinalMovilEMP | IA1: Pot_Conv | IB1: Oferta_Descuento | IC1: REMARK | ID1: Ant_Pos_Empaq | IE1: Region_Venta | IF1: Departamento_Venta | IG1: Municipio_Venta | IH1: CANAL_HOMO_DIG | II1: PRODUCTO_HOMO_DIG | IJ1: MACROSEG_DIG | IK1: TIPO_VENTA_DIG | IL1: UNIDAD_VENTA_DIG | IM1: ALIADO_VENTA_DIG | IN1: ESTADO_VARIABLE_DIG | IO1: TIPO_MEDIO_DIG | IP1: MOTIVO_QUIEBRE_DIG | IQ1: CANAL_DIR_DIG | IR1: Altas_Con_Reingreso | IS1: TipoFactura | IT1: ATR_VENTA_SOURCE | IU1: ATR_VENTA_CAMPANA | IV1: ATR_VENTA_MEDIUM | IW1: ATR_VENTA_LANDING | IX1: PLACE_ID | IY1: Oferta_empaquetada_comisiones
A2: =DAY(AVANZA[[#This Row],[FechaSeguimiento]]) -> 1 | B2: =MONTH(AVANZA[[#This Row],[FechaSeguimiento]]) -> 5 | C2: =LOWER(IF(AND(AVANZA[[#This Row],[Mes_Reg]]=MONTH(TODAY()),AND(AVANZA[[#This Row],[Dia_Reg]]>0,AVANZA[[#This Row],[Dia_Reg]]<9)),"SEMANA 1","")&IF(AND(AVANZA[[#This Row],[Mes_Reg]]=MONTH(TODAY()),AND(AVANZA[[#This Row],[Dia_Reg]]>8,AVANZA[[#This Row],[Dia_Reg]]<16)),"SEMANA 2","")&IF(AND(AVANZA[[#This Row],[Mes_Reg]]=MONTH(TODAY()),AND(AVANZA[[#This Row],[Dia_Reg]]>15,AVANZA[[#This Row],[Dia_Reg]]<23)),"SEMANA 3","")&IF(AND(AVANZA[[#This Row],[Mes_Reg]]=MONTH(TODAY()),AND(AVANZA[[#This Row],[Dia_Reg]]>22,AVANZA[[#This Row],[Dia_Reg]]<31)),"SEMANA 4","")&IF(AVANZA[[#This Row],[Mes_Reg]]<>MONTH(TODAY()),"BOLSA MES ANTERIOR","")) -> semana 1 | D2: =LOWER(IFERROR(VLOOKUP(AVANZA[[#This Row],[ID_Peticion]],CANCELADAS[#All],2,0),"")) | E2: =LOWER(IFERROR(VLOOKUP(AVANZA[[#This Row],[ID_Peticion]],CANCELADAS[#All],3,0),"")) | F2: =LOWER(IF(AVANZA[[#This Row],[CEDULA CLIENTE]]<>""," CC: " & COUNTIFS(AVANZA[CEDULA CLIENTE],AVANZA[[#This Row],[CEDULA CLIENTE]]),"")& IF(AVANZA[[#This Row],[Direccion]]<>""," DIR: " & COUNTIFS(AVANZA[Direccion],AVANZA[[#This Row],[Direccion]]),"")) -> dir: 1 | G2: =IFERROR(VLOOKUP(AVANZA[[#This Row],[Cedula_Vendedor_Atis]],PLANTA[[#All],[CEDULA]:[LINEA]],3,0),"No Cruza") -> Marisol Avella | H2: =IFERROR(VLOOKUP(AVANZA[[#This Row],[Cedula_Vendedor_Atis]],PLANTA[[#All],[CEDULA]:[LINEA]],4,0),"No Cruza") -> Fija | I2: =LOWER(IF(AVANZA[[#This Row],[ATRIBUIBLE]]="",AVANZA[[#This Row],[Variable]],AVANZA[[#This Row],[ATRIBUIBLE]])) -> terminada | J2: =IF(AVANZA[[#This Row],[Variable]]=AVANZA[[#Headers],[TERMINADA]],1,0) -> 1 | K2: =IF(AVANZA[[#This Row],[Variable]]=AVANZA[[#Headers],[ANULADA]],1,0) -> 0 | L2: =IF(AVANZA[[#This Row],[Variable]]=AVANZA[[#Headers],[PENDIENTE]],1,0) -> 0 | M2: =IF(AVANZA[[#This Row],[ESTADO AGENDA]]="AGENDADA",1,0) -> 0 | N2: =IF(AVANZA[[#This Row],[ESTADO AGENDA]]="PENDIENTE DE AGENDAR",1,0) -> 0 | O2: =IF(AVANZA[[#This Row],[ESTADO AGENDA]]="SUSPENDIDA",1,0) -> 0 | P2: {=_xlfn.XLOOKUP(AVANZA[[#This Row],[Num_Agrupacion_Pet_Atis]],Tabla1[[#All],[Numero_de_actuacion]],Tabla1[[#All],[Estado_de_la_orden]],"",0)} | Q2: {=_xlfn.XLOOKUP(AVANZA[[#This Row],[Num_Agrupacion_Pet_Atis]],Tabla1[[#All],[Numero_de_actuacion]],Tabla1[[#All],[Fecha_de_la_cita]],"",0)} | R2: {=_xlfn.XLOOKUP(AVANZA[[#This Row],[Num_Agrupacion_Pet_Atis]],Tabla1[[#All],[Numero_de_actuacion]],Tabla1[[#All],[Franja_horaria_de_la_cita]],"",0)} | S2: =IFERROR(DAY(AVANZA[[#This Row],[FECHA AGENDA]]),"") | T2: =IFERROR(MONTH(AVANZA[[#This Row],[FECHA AGENDA]]),"") | U2: {=_xlfn.XLOOKUP(AVANZA[[#This Row],[Num_Agrupacion_Pet_Atis]],Tabla1[[#All],[Numero_de_actuacion]],Tabla1[[#All],[Motivo_de_suspension]],"",0)} | V2: {=_xlfn.XLOOKUP(AVANZA[[#This Row],[Num_Agrupacion_Pet_Atis]],Tabla1[[#All],[Numero_de_actuacion]],Tabla1[[#All],[No_identificacion_cliente]],"",0)} | W2: {=_xlfn.XLOOKUP(AVANZA[[#This Row],[Num_Agrupacion_Pet_Atis]],Tabla1[[#All],[Numero_de_actuacion]],Tabla1[[#All],[Movil_de_contacto]],"",0)} | X2: =IF(OR(AVANZA[[#This Row],[ESTADO LEG]]="Legalizada grabacion",AVANZA[[#This Row],[ESTADO LEG]]="Legalizada aut"),1,0) -> 1 | Y2: =IF(OR(AVANZA[[#This Row],[ESTADO LEG]]="pdte legalizar",AVANZA[[#This Row],[ESTADO LEG]]="No cruza"),1,0) -> 0 | Z2: {=IF(AVANZA[[#This Row],[Variable]]="Terminada",LOWER(_xlfn.XLOOKUP(AVANZA[[#This Row],[ID_Peticion]],Tabla6[[#All],[NUM_PETICION]],Tabla6[[#All],[ESTADO_LEG]],"NO CRUZA",0)),AVANZA[[#This Row],[Variable]])} -> legalizada grabacion | AA2: {=_xlfn.XLOOKUP(AVANZA[[#This Row],[ID_Peticion]],Tabla6[[#All],[NUM_PETICION]],Tabla6[[#All],[DIF_DIAS]],"",0)} -> 4 | AB2: {=IFERROR(_xlfn.XLOOKUP(AVANZA[[#This Row],[ID_Peticion]],Tabla6[[#All],[NUM_PETICION]],Tabla6[[#All],[FEC_LEGAL]],"",0),"")} -> 46147 | AC2: =IF(AVANZA[[#This Row],[FECHA LEG]]<>0,IFERROR(AVANZA[[#This Row],[FECHA LEG]]-AVANZA[[#This Row],[FechaIniEstadoSubPetAtis]],0),TODAY()-AVANZA[[#This Row],[FechaIniEstadoSubPetAtis]]) -> 4 | AD2: =IF(AVANZA[[#This Row],[FINAL Vs LG]]<>0,IF(AVANZA[[#This Row],[FINAL Vs LG]]<7.1,"100%",IF(AND(AVANZA[[#This Row],[FINAL Vs LG]]>7.1,AVANZA[[#This Row],[FINAL Vs LG]]<11.1),"50%","0%")),0) -> 100% | AE2: =VLOOKUP(DAY(TODAY()),BACK!F:G,2,0) -> 14 | AF2: =BACK!$I$2 -> 24 | AG2: =IF(AVANZA[[#This Row],[Oferta_empaquetada_comisiones]]="SI",1,0) -> 1 | AH2: =IF(AVANZA[[#This Row],[Variable]]="TERMINADA",IFERROR(VLOOKUP(AVANZA[[#This Row],[SUPERVISOR]],Tabla2[#All],4,0),0),) -> 3.5 | AI2: =IF(AVANZA[[#This Row],[Producto]]="BA",1,0) -> 1 | AJ2: =IF(AVANZA[[#This Row],[Producto]]="DUO",1,0) -> 0 | AK2: =IF(AVANZA[[#This Row],[Producto]]="TRIO",1,0) -> 0 | AL2: 1624058238002044670 | AM2: -1 | AN2: -1 | AO2: 1785901244 | AP2: 46143.484 | AQ2: -1 | AR2: 2512691090 | AS2: -1 | AT2: -1 | AU2: -1 | AV2: -1 | AW2: -1 | AX2: FixedCreateSubscriber | AY2: -1 | AZ2: 2026 | BA2: 5 | BB2: 1 | BC2: -1 | BD2: Broadband Service | BE2: -1 | BF2: 20001621103978 | BG2: Convergente_MTotal_Single_Voz Ilim Nal _Ba Ancha 900Mbps_Mov Ilim_Nac_25421 | BH2: 25421 | BI2: FS202605011137041941 | BJ2: -1 | BK2: -1 | BL2: -1 | BM2: TERMINADA | BN2: Individual | BO2: 6108776323 | BP2: Movistar Total | BQ2: 2026 | BR2: 5 | BS2: 1 | BT2: 46143.618 | BU2: OS90 | BV2: 46143 | BW2: Completed | BX2: 46143 | BY2: 46143 | BZ2: Call Back To CRM | CA2: BOGOTA, D.C. | CB2: BOGOTA, D.C. | CC2: KR 121 CL 70 A-16 LA FAENA 16 APT 2 LAT:4.71684612 LON:-74.13659734 | CD2: LA FAENA | CE2: -1 | CF2: 11001000 | CG2: Bogota | CH2: ATACANTE | CI2: 1018514067 | CJ2: JHOJAN ALEXANDER JIMENEZ MELO | CK2: CANAL ONLINE | CL2: TELEVENTAS | CM2: ATENTO COLOMBIA S.A. | CN2: CANAL ON LINE - ATENTO OUT BOUND | CT2: 2 | CU2: Broadband Service | CW2: Convergente_MTotal_Single_Voz Ilim Nal _Ba Ancha 900Mbps_Mov Ilim_Nac_25421 | CX2: 25421 | DA2: SV | DB2: -1 | DF2: ALTA | DJ2: 900000 | DK2: Cliente Nuevo | DL2: Cliente Existente | DN2: BA | DR2: jajimenezme1 | DS2: JHOJAN ALEXANDER JIMENEZ MELO | DT2: 1018514067 | DV2: 1 | DW2: BOGOTA | ED2: 46143 | EE2: Occidente | EF2: 9 | EP2: 830065842-5 | ES2: 158 | FA2: CANAL ONLINE | FB2: Bogotá D.C | FD2: Bogotá D.C | FE2: Bogotá | FF2: Bogotá | FK2: ATENTO | FL2: 11001000OH_BOGALEIVA_I_7360_32050_Engativa_1ENGAT-CT3/4-43-04SS3-43-04@11001000_OH_BOGALEIVA_I_7360_32050_Engativa_1_ENGAT-CT3/4-43-04_SS3-43-04 | FN2: CANAL ON LINE - ATENTO OUT BOUND | FO2: 9900202020034 | FR2: 85900 | GB2: PON | GC2: Broadband Service | GD2: 0 | GF2: 0 | GG2: 25421 | GI2: 85900 | GJ2: 0 | GL2: 0 | GM2: 102221 | GS2: FS | GT2: 45107 | GU2: CENTRO EXP | GV2: SIN EMAIL | GW2: Si | GX2: SV | GY2: Convergente Solo Contrato | GZ2: Convergente Nuevo | HA2: ONNET | HB2: BOGOTA 1 | HC2: BOGOTA 1 | HD2: BOGOTA NORTE | HE2: Individual | HF2: 471574135 | HG2: Venta mismo mes (F+M) mismo Canal_mismo Aliado | HH2: 52077088 | HI2: 1. Radicadas | HJ2: 46150 | HK2: ATENTO COLOMBIA S.A. | HL2: CANAL ONLINE | HM2: 9900202020034 | HN2: CANAL ON LINE - ATENTO OUT BOUND | HO2: JHOJAN ALEXANDER JIMENEZ MELO | HP2: 1018514067 | HR2: Asistido | HV2: 85900 | HW2: SI | HX2: Radicada - No nato igual a NO | HY2: 103568 | HZ2: 17668 | IA2: SI | IB2: NO | IE2: BOGOTA | IF2: BOGOTA | IG2: BOGOTA | IH2: Digital | II2: Fibra | IJ2: B2C | IK2: Asistido | IL2: Outbound | IM2: Atento | IN2: Alta | IP2: - | IQ2: Digital | IS2: ELECTRONICA | IT2: WhatsApp Bot | IY2: SI
A3: =DAY(AVANZA[[#This Row],[FechaSeguimiento]]) -> 1 | B3: =MONTH(AVANZA[[#This Row],[FechaSeguimiento]]) -> 5 | C3: =LOWER(IF(AND(AVANZA[[#This Row],[Mes_Reg]]=MONTH(TODAY()),AND(AVANZA[[#This Row],[Dia_Reg]]>0,AVANZA[[#This Row],[Dia_Reg]]<9)),"SEMANA 1","")&IF(AND(AVANZA[[#This Row],[Mes_Reg]]=MONTH(TODAY()),AND(AVANZA[[#This Row],[Dia_Reg]]>8,AVANZA[[#This Row],[Dia_Reg]]<16)),"SEMANA 2","")&IF(AND(AVANZA[[#This Row],[Mes_Reg]]=MONTH(TODAY()),AND(AVANZA[[#This Row],[Dia_Reg]]>15,AVANZA[[#This Row],[Dia_Reg]]<23)),"SEMANA 3","")&IF(AND(AVANZA[[#This Row],[Mes_Reg]]=MONTH(TODAY()),AND(AVANZA[[#This Row],[Dia_Reg]]>22,AVANZA[[#This Row],[Dia_Reg]]<31)),"SEMANA 4","")&IF(AVANZA[[#This Row],[Mes_Reg]]<>MONTH(TODAY()),"BOLSA MES ANTERIOR","")) -> bolsa mes anterior | D3: =LOWER(IFERROR(VLOOKUP(AVANZA[[#This Row],[ID_Peticion]],CANCELADAS[#All],2,0),"")) | E3: =LOWER(IFERROR(VLOOKUP(AVANZA[[#This Row],[ID_Peticion]],CANCELADAS[#All],3,0),"")) | F3: =LOWER(IF(AVANZA[[#This Row],[CEDULA CLIENTE]]<>""," CC: " & COUNTIFS(AVANZA[CEDULA CLIENTE],AVANZA[[#This Row],[CEDULA CLIENTE]]),"")& IF(AVANZA[[#This Row],[Direccion]]<>""," DIR: " & COUNTIFS(AVANZA[Direccion],AVANZA[[#This Row],[Direccion]]),"")) -> dir: 1 | G3: =IFERROR(VLOOKUP(AVANZA[[#This Row],[Cedula_Vendedor_Atis]],PLANTA[[#All],[CEDULA]:[LINEA]],3,0),"No Cruza") -> Marisol Avella | H3: =IFERROR(VLOOKUP(AVANZA[[#This Row],[Cedula_Vendedor_Atis]],PLANTA[[#All],[CEDULA]:[LINEA]],4,0),"No Cruza") -> Fija | I3: =LOWER(IF(AVANZA[[#This Row],[ATRIBUIBLE]]="",AVANZA[[#This Row],[Variable]],AVANZA[[#This Row],[ATRIBUIBLE]])) -> terminada | J3: =IF(AVANZA[[#This Row],[Variable]]=AVANZA[[#Headers],[TERMINADA]],1,0) -> 1 | K3: =IF(AVANZA[[#This Row],[Variable]]=AVANZA[[#Headers],[ANULADA]],1,0) -> 0 | L3: =IF(AVANZA[[#This Row],[Variable]]=AVANZA[[#Headers],[PENDIENTE]],1,0) -> 0 | M3: =IF(AVANZA[[#This Row],[ESTADO AGENDA]]="AGENDADA",1,0) -> 0 | N3: =IF(AVANZA[[#This Row],[ESTADO AGENDA]]="PENDIENTE DE AGENDAR",1,0) -> 0 | O3: =IF(AVANZA[[#This Row],[ESTADO AGENDA]]="SUSPENDIDA",1,0) -> 0 | P3: {=_xlfn.XLOOKUP(AVANZA[[#This Row],[Num_Agrupacion_Pet_Atis]],Tabla1[[#All],[Numero_de_actuacion]],Tabla1[[#All],[Estado_de_la_orden]],"",0)} | Q3: {=_xlfn.XLOOKUP(AVANZA[[#This Row],[Num_Agrupacion_Pet_Atis]],Tabla1[[#All],[Numero_de_actuacion]],Tabla1[[#All],[Fecha_de_la_cita]],"",0)} | R3: {=_xlfn.XLOOKUP(AVANZA[[#This Row],[Num_Agrupacion_Pet_Atis]],Tabla1[[#All],[Numero_de_actuacion]],Tabla1[[#All],[Franja_horaria_de_la_cita]],"",0)} | S3: =IFERROR(DAY(AVANZA[[#This Row],[FECHA AGENDA]]),"") | T3: =IFERROR(MONTH(AVANZA[[#This Row],[FECHA AGENDA]]),"") | U3: {=_xlfn.XLOOKUP(AVANZA[[#This Row],[Num_Agrupacion_Pet_Atis]],Tabla1[[#All],[Numero_de_actuacion]],Tabla1[[#All],[Motivo_de_suspension]],"",0)} | V3: {=_xlfn.XLOOKUP(AVANZA[[#This Row],[Num_Agrupacion_Pet_Atis]],Tabla1[[#All],[Numero_de_actuacion]],Tabla1[[#All],[No_identificacion_cliente]],"",0)} | W3: {=_xlfn.XLOOKUP(AVANZA[[#This Row],[Num_Agrupacion_Pet_Atis]],Tabla1[[#All],[Numero_de_actuacion]],Tabla1[[#All],[Movil_de_contacto]],"",0)} | X3: =IF(OR(AVANZA[[#This Row],[ESTADO LEG]]="Legalizada grabacion",AVANZA[[#This Row],[ESTADO LEG]]="Legalizada aut"),1,0) -> 1 | Y3: =IF(OR(AVANZA[[#This Row],[ESTADO LEG]]="pdte legalizar",AVANZA[[#This Row],[ESTADO LEG]]="No cruza"),1,0) -> 0 | Z3: {=IF(AVANZA[[#This Row],[Variable]]="Terminada",LOWER(_xlfn.XLOOKUP(AVANZA[[#This Row],[ID_Peticion]],Tabla6[[#All],[NUM_PETICION]],Tabla6[[#All],[ESTADO_LEG]],"NO CRUZA",0)),AVANZA[[#This Row],[Variable]])} -> legalizada grabacion | AA3: {=_xlfn.XLOOKUP(AVANZA[[#This Row],[ID_Peticion]],Tabla6[[#All],[NUM_PETICION]],Tabla6[[#All],[DIF_DIAS]],"",0)} -> 4 | AB3: {=IFERROR(_xlfn.XLOOKUP(AVANZA[[#This Row],[ID_Peticion]],Tabla6[[#All],[NUM_PETICION]],Tabla6[[#All],[FEC_LEGAL]],"",0),"")} -> 46147 | AC3: =IF(AVANZA[[#This Row],[FECHA LEG]]<>0,IFERROR(AVANZA[[#This Row],[FECHA LEG]]-AVANZA[[#This Row],[FechaIniEstadoSubPetAtis]],0),TODAY()-AVANZA[[#This Row],[FechaIniEstadoSubPetAtis]]) -> 4 | AD3: =IF(AVANZA[[#This Row],[FINAL Vs LG]]<>0,IF(AVANZA[[#This Row],[FINAL Vs LG]]<7.1,"100%",IF(AND(AVANZA[[#This Row],[FINAL Vs LG]]>7.1,AVANZA[[#This Row],[FINAL Vs LG]]<11.1),"50%","0%")),0) -> 100% | AE3: =VLOOKUP(DAY(TODAY()),BACK!F:G,2,0) -> 14 | AF3: =BACK!$I$2 -> 24 | AG3: =IF(AVANZA[[#This Row],[Oferta_empaquetada_comisiones]]="SI",1,0) -> 0 | AH3: =IF(AVANZA[[#This Row],[Variable]]="TERMINADA",IFERROR(VLOOKUP(AVANZA[[#This Row],[SUPERVISOR]],Tabla2[#All],4,0),0),) -> 3.5 | AI3: =IF(AVANZA[[#This Row],[Producto]]="BA",1,0) -> 1 | AJ3: =IF(AVANZA[[#This Row],[Producto]]="DUO",1,0) -> 0 | AK3: =IF(AVANZA[[#This Row],[Producto]]="TRIO",1,0) -> 0 | AL3: 1648048636331251387 | AM3: -1 | AN3: -1 | AO3: 1785369241 | AP3: 46142.386 | AQ3: -1 | AR3: 2512688904 | AS3: -1 | AT3: -1 | AU3: -1 | AV3: -1 | AW3: -1 | AX3: FixedCreateSubscriber | AY3: -1 | AZ3: 2026 | BA3: 5 | BB3: 1 | BC3: -1 | BD3: Broadband Service | BE3: -1 | BF3: 20001620503190 | BG3: Plan Banda Ancha 900Mbps Solo Internet_Nac_25423 | BH3: 25423 | BI3: FS202604300915040963 | BJ3: -1 | BK3: -1 | BL3: -1 | BM3: TERMINADA | BN3: Individual | BO3: 6108760564 | BP3: Movistar Total | BQ3: 2026 | BR3: 4 | BS3: 30 | BT3: 46143.43 | BU3: OS90 | BV3: 46143 | BW3: Completed | BX3: 46142 | BY3: 46143 | BZ3: Call Back To CRM | CA3: MEDELLIN | CB3: ANTIOQUIA | CC3: KR 84 CL 77 C C-57 BELLO HORIZONTE 57 APT 201 LAT:6.28199227 LON:-75.58856262 | CD3: BELLO HORIZONTE | CE3: -1 | CF3: 05001000 | CG3: Antioquia - Choco | CH3: SIN PRESENCIA | CI3: 1073250775 | CJ3: SHARON NATALIA GONZALEZ CAAADULCE | CK3: CANAL ONLINE | CL3: ON LINE | CM3: ATENTO COLOMBIA S.A. | CN3: CANAL ON LINE - ATENTO CLICK TO CALL | CT3: 2 | CU3: Broadband Service | CW3: Plan Banda Ancha 900Mbps Solo Internet_Nac_25423 | CX3: 25423 | DA3: SV | DB3: -1 | DF3: ALTA | DJ3: 900000 | DK3: Cliente Nuevo | DL3: Cliente Existente | DN3: BA | DR3: sngonzalezca | DS3: SHARON NATALIA GONZALEZ CAAADULCE | DT3: 1073250775 | DV3: 1 | DW3: NOROCCIDENTE | ED3: 46143 | EF3: 9 | EP3: 830065842-5 | ES3: 3_1 | FA3: CANAL ONLINE | FB3: Antioquia | FD3: Antioquia | FE3: Medellín | FF3: Medellín | FK3: ATENTO | FL3: 5001000OH_ANTALCLLC_I_7360_Medellin_Castilla_3CASTI-CT3/4-60-06SS3-60-06@5001000_OH_ANTALCLLC_I_7360_Medellin_Castilla_3_CASTI-CT3/4-60-06_SS3-60-06 | FN3: CANAL ON LINE - ATENTO CLICK TO CALL | FO3: 9900202020033 | FR3: 94990 | GB3: PON | GC3: Broadband Service | GD3: 0 | GF3: 0 | GG3: 25423 | GI3: 94990 | GJ3: 0 | GL3: 0 | GM3: 113038 | GS3: FS | GT3: 45473 | GU3: CENTRO EXP | GV3: VALIDADO | GW3: Si | GX3: SV | GY3: Convergente Solo Contrato | GZ3: Convergente Nuevo | HA3: ONNET | HB3: MEDELLIN | HC3: MEDELLIN | HD3: MEDELLIN + NOROCCIDENTE | HE3: Individual | HF3: 628075585 | HG3: Venta mismo mes (F+M) diferente Canal_diferente Al | HH3: 1025889366 | HI3: 1. Radicadas | HJ3: 46151 | HK3: BECALL | HL3: TELEVENTAS | HM3: 9900210050001 | HN3: TELEVENTAS - BECALL | HO3: LUIS ALEJANDRO NIETO MARIN | HP3: 1116434451 | HR3: Asistido | HV3: 94990 | HW3: NO | HY3: 0 | HZ3: 0 | IA3: SI | IB3: NO | IE3: BOGOTA | IF3: BOGOTA | IG3: BOGOTA | IH3: Digital | II3: Fibra | IJ3: B2C | IK3: Asistido | IL3: C2C | IM3: Atento | IN3: Alta | IP3: - | IQ3: Digital | IS3: ELECTRONICA | IT3: WhatsApp Bot | IY3: NO
A4: =DAY(AVANZA[[#This Row],[FechaSeguimiento]]) -> 1 | B4: =MONTH(AVANZA[[#This Row],[FechaSeguimiento]]) -> 5 | C4: =LOWER(IF(AND(AVANZA[[#This Row],[Mes_Reg]]=MONTH(TODAY()),AND(AVANZA[[#This Row],[Dia_Reg]]>0,AVANZA[[#This Row],[Dia_Reg]]<9)),"SEMANA 1","")&IF(AND(AVANZA[[#This Row],[Mes_Reg]]=MONTH(TODAY()),AND(AVANZA[[#This Row],[Dia_Reg]]>8,AVANZA[[#This Row],[Dia_Reg]]<16)),"SEMANA 2","")&IF(AND(AVANZA[[#This Row],[Mes_Reg]]=MONTH(TODAY()),AND(AVANZA[[#This Row],[Dia_Reg]]>15,AVANZA[[#This Row],[Dia_Reg]]<23)),"SEMANA 3","")&IF(AND(AVANZA[[#This Row],[Mes_Reg]]=MONTH(TODAY()),AND(AVANZA[[#This Row],[Dia_Reg]]>22,AVANZA[[#This Row],[Dia_Reg]]<31)),"SEMANA 4","")&IF(AVANZA[[#This Row],[Mes_Reg]]<>MONTH(TODAY()),"BOLSA MES ANTERIOR","")) -> bolsa mes anterior | D4: =LOWER(IFERROR(VLOOKUP(AVANZA[[#This Row],[ID_Peticion]],CANCELADAS[#All],2,0),"")) | E4: =LOWER(IFERROR(VLOOKUP(AVANZA[[#This Row],[ID_Peticion]],CANCELADAS[#All],3,0),"")) | F4: =LOWER(IF(AVANZA[[#This Row],[CEDULA CLIENTE]]<>""," CC: " & COUNTIFS(AVANZA[CEDULA CLIENTE],AVANZA[[#This Row],[CEDULA CLIENTE]]),"")& IF(AVANZA[[#This Row],[Direccion]]<>""," DIR: " & COUNTIFS(AVANZA[Direccion],AVANZA[[#This Row],[Direccion]]),"")) -> dir: 1 | G4: =IFERROR(VLOOKUP(AVANZA[[#This Row],[Cedula_Vendedor_Atis]],PLANTA[[#All],[CEDULA]:[LINEA]],3,0),"No Cruza") -> Marisol Avella | H4: =IFERROR(VLOOKUP(AVANZA[[#This Row],[Cedula_Vendedor_Atis]],PLANTA[[#All],[CEDULA]:[LINEA]],4,0),"No Cruza") -> Fija | I4: =LOWER(IF(AVANZA[[#This Row],[ATRIBUIBLE]]="",AVANZA[[#This Row],[Variable]],AVANZA[[#This Row],[ATRIBUIBLE]])) -> terminada | J4: =IF(AVANZA[[#This Row],[Variable]]=AVANZA[[#Headers],[TERMINADA]],1,0) -> 1 | K4: =IF(AVANZA[[#This Row],[Variable]]=AVANZA[[#Headers],[ANULADA]],1,0) -> 0 | L4: =IF(AVANZA[[#This Row],[Variable]]=AVANZA[[#Headers],[PENDIENTE]],1,0) -> 0 | M4: =IF(AVANZA[[#This Row],[ESTADO AGENDA]]="AGENDADA",1,0) -> 0 | N4: =IF(AVANZA[[#This Row],[ESTADO AGENDA]]="PENDIENTE DE AGENDAR",1,0) -> 0 | O4: =IF(AVANZA[[#This Row],[ESTADO AGENDA]]="SUSPENDIDA",1,0) -> 0 | P4: {=_xlfn.XLOOKUP(AVANZA[[#This Row],[Num_Agrupacion_Pet_Atis]],Tabla1[[#All],[Numero_de_actuacion]],Tabla1[[#All],[Estado_de_la_orden]],"",0)} | Q4: {=_xlfn.XLOOKUP(AVANZA[[#This Row],[Num_Agrupacion_Pet_Atis]],Tabla1[[#All],[Numero_de_actuacion]],Tabla1[[#All],[Fecha_de_la_cita]],"",0)} | R4: {=_xlfn.XLOOKUP(AVANZA[[#This Row],[Num_Agrupacion_Pet_Atis]],Tabla1[[#All],[Numero_de_actuacion]],Tabla1[[#All],[Franja_horaria_de_la_cita]],"",0)} | S4: =IFERROR(DAY(AVANZA[[#This Row],[FECHA AGENDA]]),"") | T4: =IFERROR(MONTH(AVANZA[[#This Row],[FECHA AGENDA]]),"") | U4: {=_xlfn.XLOOKUP(AVANZA[[#This Row],[Num_Agrupacion_Pet_Atis]],Tabla1[[#All],[Numero_de_actuacion]],Tabla1[[#All],[Motivo_de_suspension]],"",0)} | V4: {=_xlfn.XLOOKUP(AVANZA[[#This Row],[Num_Agrupacion_Pet_Atis]],Tabla1[[#All],[Numero_de_actuacion]],Tabla1[[#All],[No_identificacion_cliente]],"",0)} | W4: {=_xlfn.XLOOKUP(AVANZA[[#This Row],[Num_Agrupacion_Pet_Atis]],Tabla1[[#All],[Numero_de_actuacion]],Tabla1[[#All],[Movil_de_contacto]],"",0)} | X4: =IF(OR(AVANZA[[#This Row],[ESTADO LEG]]="Legalizada grabacion",AVANZA[[#This Row],[ESTADO LEG]]="Legalizada aut"),1,0) -> 1 | Y4: =IF(OR(AVANZA[[#This Row],[ESTADO LEG]]="pdte legalizar",AVANZA[[#This Row],[ESTADO LEG]]="No cruza"),1,0) -> 0 | Z4: {=IF(AVANZA[[#This Row],[Variable]]="Terminada",LOWER(_xlfn.XLOOKUP(AVANZA[[#This Row],[ID_Peticion]],Tabla6[[#All],[NUM_PETICION]],Tabla6[[#All],[ESTADO_LEG]],"NO CRUZA",0)),AVANZA[[#This Row],[Variable]])} -> legalizada grabacion | AA4: {=_xlfn.XLOOKUP(AVANZA[[#This Row],[ID_Peticion]],Tabla6[[#All],[NUM_PETICION]],Tabla6[[#All],[DIF_DIAS]],"",0)} -> 4 | AB4: {=IFERROR(_xlfn.XLOOKUP(AVANZA[[#This Row],[ID_Peticion]],Tabla6[[#All],[NUM_PETICION]],Tabla6[[#All],[FEC_LEGAL]],"",0),"")} -> 46147 | AC4: =IF(AVANZA[[#This Row],[FECHA LEG]]<>0,IFERROR(AVANZA[[#This Row],[FECHA LEG]]-AVANZA[[#This Row],[FechaIniEstadoSubPetAtis]],0),TODAY()-AVANZA[[#This Row],[FechaIniEstadoSubPetAtis]]) -> 4 | AD4: =IF(AVANZA[[#This Row],[FINAL Vs LG]]<>0,IF(AVANZA[[#This Row],[FINAL Vs LG]]<7.1,"100%",IF(AND(AVANZA[[#This Row],[FINAL Vs LG]]>7.1,AVANZA[[#This Row],[FINAL Vs LG]]<11.1),"50%","0%")),0) -> 100% | AE4: =VLOOKUP(DAY(TODAY()),BACK!F:G,2,0) -> 14 | AF4: =BACK!$I$2 -> 24 | AG4: =IF(AVANZA[[#This Row],[Oferta_empaquetada_comisiones]]="SI",1,0) -> 0 | AH4: =IF(AVANZA[[#This Row],[Variable]]="TERMINADA",IFERROR(VLOOKUP(AVANZA[[#This Row],[SUPERVISOR]],Tabla2[#All],4,0),0),) -> 3.5 | AI4: =IF(AVANZA[[#This Row],[Producto]]="BA",1,0) -> 1 | AJ4: =IF(AVANZA[[#This Row],[Producto]]="DUO",1,0) -> 0 | AK4: =IF(AVANZA[[#This Row],[Producto]]="TRIO",1,0) -> 0 | AL4: 1624058238002044670 | AM4: -1 | AN4: -1 | AO4: 1784982688 | AP4: 46141.697 | AQ4: -1 | AR4: 2512687770 | AS4: -1 | AT4: -1 | AU4: -1 | AV4: -1 | AW4: -1 | AX4: FixedCreateSubscriber | AY4: -1 | AZ4: 2026 | BA4: 5 | BB4: 1 | BC4: -1 | BD4: Broadband Service | BE4: -1 | BF4: 20001620107451 | BG4: Plan Banda Ancha 900Mbps Solo Internet_Nac_25423 | BH4: 25423 | BI4: FS202604291641141607 | BJ4: -1 | BK4: -1 | BL4: -1 | BM4: TERMINADA | BN4: Individual | BO4: 6108749533 | BP4: Gold | BQ4: 2026 | BR4: 4 | BS4: 29 | BT4: 46143.449 | BU4: OS90 | BV4: 46143 | BW4: Completed | BX4: 46141 | BY4: 46143 | BZ4: Call Back To CRM | CA4: MEDELLIN | CB4: ANTIOQUIA | CC4: CL 97 KR 76-119 SAN MARTIN DE PORRES 119 APT 201 LAT:6.2952141966666 LON:-75.58087016666 | CD4: SAN MARTIN DE PORRES | CE4: -1 | CF4: 05001000 | CG4: Antioquia - Choco | CH4: SIN PRESENCIA | CI4: 1018514067 | CJ4: JHOJAN ALEXANDER JIMENEZ MELO | CK4: CANAL ONLINE | CL4: TELEVENTAS | CM4: ATENTO COLOMBIA S.A. | CN4: CANAL ON LINE - ATENTO OUT BOUND | CT4: 2 | CU4: Broadband Service | CW4: Plan Banda Ancha 900Mbps Solo Internet_Nac_25423 | CX4: 25423 | DA4: SV | DB4: -1 | DF4: ALTA | DJ4: 900000 | DK4: Cliente Nuevo | DL4: Cliente Existente | DN4: BA | DR4: jajimenezme1 | DS4: JHOJAN ALEXANDER JIMENEZ MELO | DT4: 1018514067 | DV4: 1 | DW4: NOROCCIDENTE | ED4: 46143 | EF4: 5 | EP4: 830065842-5 | ES4: 3_1 | FA4: CANAL ONLINE | FB4: Antioquia | FD4: Antioquia | FE4: Medellín | FF4: Medellín | FK4: ATENTO | FL4: 5001000OH_ANTALCLLA_I_7360_Medellin_CastillaCASTI-CT3/4-19-03SS4-19-03@5001000_OH_ANTALCLLA_I_7360_Medellin_Castilla_CASTI-CT3/4-19-03_SS4-19-03 | FN4: CANAL ON LINE - ATENTO OUT BOUND | FO4: 9900202020034 | FR4: 94990 | GB4: PON | GC4: Broadband Service | GD4: 0 | GF4: 0 | GG4: 25423 | GI4: 94990 | GJ4: 0 | GL4: 0 | GM4: 113038 | GS4: FS | GT4: 45322 | GU4: CENTRO EXP | GV4: SIN EMAIL | GW4: No | GZ4: No Convergente | HA4: ONNET | HB4: MEDELLIN | HC4: MEDELLIN | HD4: MEDELLIN + NOROCCIDENTE | HE4: Individual | HF4: 629575580 | HR4: Asistido | HV4: 94990 | HW4: NO | HY4: 0 | HZ4: 0 | IA4: NO | IB4: NO | IE4: BOGOTA | IF4: BOGOTA | IG4: BOGOTA | IH4: Digital | II4: Fibra | IJ4: B2C | IK4: Asistido | IL4: Inbound | IM4: Atento | IN4: Alta | IP4: - | IQ4: Digital | IS4: ELECTRONICA | IT4: Inbound | IY4: NO
A5: =DAY(AVANZA[[#This Row],[FechaSeguimiento]]) -> 1 | B5: =MONTH(AVANZA[[#This Row],[FechaSeguimiento]]) -> 5 | C5: =LOWER(IF(AND(AVANZA[[#This Row],[Mes_Reg]]=MONTH(TODAY()),AND(AVANZA[[#This Row],[Dia_Reg]]>0,AVANZA[[#This Row],[Dia_Reg]]<9)),"SEMANA 1","")&IF(AND(AVANZA[[#This Row],[Mes_Reg]]=MONTH(TODAY()),AND(AVANZA[[#This Row],[Dia_Reg]]>8,AVANZA[[#This Row],[Dia_Reg]]<16)),"SEMANA 2","")&IF(AND(AVANZA[[#This Row],[Mes_Reg]]=MONTH(TODAY()),AND(AVANZA[[#This Row],[Dia_Reg]]>15,AVANZA[[#This Row],[Dia_Reg]]<23)),"SEMANA 3","")&IF(AND(AVANZA[[#This Row],[Mes_Reg]]=MONTH(TODAY()),AND(AVANZA[[#This Row],[Dia_Reg]]>22,AVANZA[[#This Row],[Dia_Reg]]<31)),"SEMANA 4","")&IF(AVANZA[[#This Row],[Mes_Reg]]<>MONTH(TODAY()),"BOLSA MES ANTERIOR","")) -> bolsa mes anterior | D5: =LOWER(IFERROR(VLOOKUP(AVANZA[[#This Row],[ID_Peticion]],CANCELADAS[#All],2,0),"")) -> carrusel | E5: =LOWER(IFERROR(VLOOKUP(AVANZA[[#This Row],[ID_Peticion]],CANCELADAS[#All],3,0),"")) -> carrusel | F5: =LOWER(IF(AVANZA[[#This Row],[CEDULA CLIENTE]]<>""," CC: " & COUNTIFS(AVANZA[CEDULA CLIENTE],AVANZA[[#This Row],[CEDULA CLIENTE]]),"")& IF(AVANZA[[#This Row],[Direccion]]<>""," DIR: " & COUNTIFS(AVANZA[Direccion],AVANZA[[#This Row],[Direccion]]),"")) -> dir: 1 | G5: =IFERROR(VLOOKUP(AVANZA[[#This Row],[Cedula_Vendedor_Atis]],PLANTA[[#All],[CEDULA]:[LINEA]],3,0),"No Cruza") -> Marisol Avella | H5: =IFERROR(VLOOKUP(AVANZA[[#This Row],[Cedula_Vendedor_Atis]],PLANTA[[#All],[CEDULA]:[LINEA]],4,0),"No Cruza") -> Fija | I5: =LOWER(IF(AVANZA[[#This Row],[ATRIBUIBLE]]="",AVANZA[[#This Row],[Variable]],AVANZA[[#This Row],[ATRIBUIBLE]])) -> carrusel | J5: =IF(AVANZA[[#This Row],[Variable]]=AVANZA[[#Headers],[TERMINADA]],1,0) -> 0 | K5: =IF(AVANZA[[#This Row],[Variable]]=AVANZA[[#Headers],[ANULADA]],1,0) -> 1 | L5: =IF(AVANZA[[#This Row],[Variable]]=AVANZA[[#Headers],[PENDIENTE]],1,0) -> 0 | M5: =IF(AVANZA[[#This Row],[ESTADO AGENDA]]="AGENDADA",1,0) -> 0 | N5: =IF(AVANZA[[#This Row],[ESTADO AGENDA]]="PENDIENTE DE AGENDAR",1,0) -> 0 | O5: =IF(AVANZA[[#This Row],[ESTADO AGENDA]]="SUSPENDIDA",1,0) -> 0 | P5: {=_xlfn.XLOOKUP(AVANZA[[#This Row],[Num_Agrupacion_Pet_Atis]],Tabla1[[#All],[Numero_de_actuacion]],Tabla1[[#All],[Estado_de_la_orden]],"",0)} | Q5: {=_xlfn.XLOOKUP(AVANZA[[#This Row],[Num_Agrupacion_Pet_Atis]],Tabla1[[#All],[Numero_de_actuacion]],Tabla1[[#All],[Fecha_de_la_cita]],"",0)} | R5: {=_xlfn.XLOOKUP(AVANZA[[#This Row],[Num_Agrupacion_Pet_Atis]],Tabla1[[#All],[Numero_de_actuacion]],Tabla1[[#All],[Franja_horaria_de_la_cita]],"",0)} | S5: =IFERROR(DAY(AVANZA[[#This Row],[FECHA AGENDA]]),"") | T5: =IFERROR(MONTH(AVANZA[[#This Row],[FECHA AGENDA]]),"") | U5: {=_xlfn.XLOOKUP(AVANZA[[#This Row],[Num_Agrupacion_Pet_Atis]],Tabla1[[#All],[Numero_de_actuacion]],Tabla1[[#All],[Motivo_de_suspension]],"",0)} | V5: {=_xlfn.XLOOKUP(AVANZA[[#This Row],[Num_Agrupacion_Pet_Atis]],Tabla1[[#All],[Numero_de_actuacion]],Tabla1[[#All],[No_identificacion_cliente]],"",0)} | W5: {=_xlfn.XLOOKUP(AVANZA[[#This Row],[Num_Agrupacion_Pet_Atis]],Tabla1[[#All],[Numero_de_actuacion]],Tabla1[[#All],[Movil_de_contacto]],"",0)} | X5: =IF(OR(AVANZA[[#This Row],[ESTADO LEG]]="Legalizada grabacion",AVANZA[[#This Row],[ESTADO LEG]]="Legalizada aut"),1,0) -> 0 | Y5: =IF(OR(AVANZA[[#This Row],[ESTADO LEG]]="pdte legalizar",AVANZA[[#This Row],[ESTADO LEG]]="No cruza"),1,0) -> 0 | Z5: {=IF(AVANZA[[#This Row],[Variable]]="Terminada",LOWER(_xlfn.XLOOKUP(AVANZA[[#This Row],[ID_Peticion]],Tabla6[[#All],[NUM_PETICION]],Tabla6[[#All],[ESTADO_LEG]],"NO CRUZA",0)),AVANZA[[#This Row],[Variable]])} -> ANULADA | AA5: {=_xlfn.XLOOKUP(AVANZA[[#This Row],[ID_Peticion]],Tabla6[[#All],[NUM_PETICION]],Tabla6[[#All],[DIF_DIAS]],"",0)} | AB5: {=IFERROR(_xlfn.XLOOKUP(AVANZA[[#This Row],[ID_Peticion]],Tabla6[[#All],[NUM_PETICION]],Tabla6[[#All],[FEC_LEGAL]],"",0),"")} | AC5: =IF(AVANZA[[#This Row],[FECHA LEG]]<>0,IFERROR(AVANZA[[#This Row],[FECHA LEG]]-AVANZA[[#This Row],[FechaIniEstadoSubPetAtis]],0),TODAY()-AVANZA[[#This Row],[FechaIniEstadoSubPetAtis]]) -> 0 | AD5: =IF(AVANZA[[#This Row],[FINAL Vs LG]]<>0,IF(AVANZA[[#This Row],[FINAL Vs LG]]<7.1,"100%",IF(AND(AVANZA[[#This Row],[FINAL Vs LG]]>7.1,AVANZA[[#This Row],[FINAL Vs LG]]<11.1),"50%","0%")),0) -> 0 | AE5: =VLOOKUP(DAY(TODAY()),BACK!F:G,2,0) -> 14 | AF5: =BACK!$I$2 -> 24 | AG5: =IF(AVANZA[[#This Row],[Oferta_empaquetada_comisiones]]="SI",1,0) -> 0 | AH5: =IF(AVANZA[[#This Row],[Variable]]="TERMINADA",IFERROR(VLOOKUP(AVANZA[[#This Row],[SUPERVISOR]],Tabla2[#All],4,0),0),) -> 0 | AI5: =IF(AVANZA[[#This Row],[Producto]]="BA",1,0) -> 1 | AJ5: =IF(AVANZA[[#This Row],[Producto]]="DUO",1,0) -> 0 | AK5: =IF(AVANZA[[#This Row],[Producto]]="TRIO",1,0) -> 0 | AL5: 1760285521955967900 | AM5: -1 | AN5: -1 | AO5: 1784153960 | AP5: 46140.473 | AQ5: -1 | AR5: 2512683151 | AS5: -1 | AT5: -1 | AU5: -1 | AV5: -1 | AW5: -1 | AX5: FixedCreateSubscriber | AY5: -1 | AZ5: 2026 | BA5: 5 | BB5: 1 | BC5: -1 | BD5: Broadband Service | BE5: -1 | BF5: 20001619384694 | BG5: Plan Banda Ancha 900Mbps Solo Internet_Nac_25423 | BH5: 25423 | BJ5: -1 | BK5: -1 | BL5: -1 | BM5: ANULADA | BN5: Individual | BO5: 6108731113 | BP5: Gold | BQ5: 2026 | BR5: 4 | BS5: 28 | BT5: 46143.514 | BU5: OS80 | BV5: 46143 | BW5: Cancelled | CA5: BOGOTA, D.C. | CB5: BOGOTA, D.C. | CC5: KR 18 CL 15-36 SAN VICTORINO 36 TOR 2 APT 4016 LAT:4.60836197 LON:-74.08179765 | CD5: SAN VICTORINO | CE5: -1 | CF5: 11001000 | CG5: Bogota | CH5: ATACANTE | CI5: 1063565638 | CJ5: JOYNNER FERNANDO BRISENO OLIVIERI | CK5: CANAL ONLINE | CL5: TELEVENTAS | CM5: ATENTO COLOMBIA S.A. | CN5: CANAL ON LINE - ATENTO OUT BOUND | CT5: 3 | CU5: Broadband Service | CW5: Plan Banda Ancha 900Mbps Solo Internet_Nac_25423 | CX5: 25423 | CY5: Anulada fraude marcada por campo remark | DA5: SV | DB5: -1 | DF5: ANULADA FRAUDE - REMARK | DJ5: 900000 | DK5: Cliente Nuevo | DL5: Cliente Nuevo | DN5: BA | DR5: jbrisenool | DS5: JOYNNER FERNANDO BRISENO OLIVIERI | DT5: 1063565638 | DV5: 1 | DW5: BOGOTA | EB5: 1 | ED5: 46143 | EF5: 5 | EP5: 830065842-5 | FA5: CANAL ONLINE | FB5: Bogotá D.C | FD5: Bogotá D.C | FE5: Bogotá | FF5: Bogotá | FK5: ATENTO | FN5: CANAL ON LINE - ATENTO OUT BOUND | FO5: 9900202020034 | FR5: 0 | GB5: PON | GM5: 0 | GS5: FS | GU5: CENTRO EXP | GW5: No | GZ5: No Convergente | HE5: Individual | HF5: 460574080 | HR5: Asistido | HV5: 94990 | HW5: NO | HY5: 0 | HZ5: 0 | IA5: SI | IB5: NO | IC5: The Fraud order (Carrusel) is cancelled by SOM. | IE5: BOGOTA | IF5: BOGOTA | IG5: BOGOTA | IH5: Digital | II5: Fibra | IJ5: B2C | IK5: Asistido | IL5: Outbound | IM5: Atento | IN5: - | IP5: - | IQ5: Digital | IR5: 0 | IS5: ELECTRONICA | IY5: NO
A6: =DAY(AVANZA[[#This Row],[FechaSeguimiento]]) -> 1 | B6: =MONTH(AVANZA[[#This Row],[FechaSeguimiento]]) -> 5 | C6: =LOWER(IF(AND(AVANZA[[#This Row],[Mes_Reg]]=MONTH(TODAY()),AND(AVANZA[[#This Row],[Dia_Reg]]>0,AVANZA[[#This Row],[Dia_Reg]]<9)),"SEMANA 1","")&IF(AND(AVANZA[[#This Row],[Mes_Reg]]=MONTH(TODAY()),AND(AVANZA[[#This Row],[Dia_Reg]]>8,AVANZA[[#This Row],[Dia_Reg]]<16)),"SEMANA 2","")&IF(AND(AVANZA[[#This Row],[Mes_Reg]]=MONTH(TODAY()),AND(AVANZA[[#This Row],[Dia_Reg]]>15,AVANZA[[#This Row],[Dia_Reg]]<23)),"SEMANA 3","")&IF(AND(AVANZA[[#This Row],[Mes_Reg]]=MONTH(TODAY()),AND(AVANZA[[#This Row],[Dia_Reg]]>22,AVANZA[[#This Row],[Dia_Reg]]<31)),"SEMANA 4","")&IF(AVANZA[[#This Row],[Mes_Reg]]<>MONTH(TODAY()),"BOLSA MES ANTERIOR","")) -> bolsa mes anterior | D6: =LOWER(IFERROR(VLOOKUP(AVANZA[[#This Row],[ID_Peticion]],CANCELADAS[#All],2,0),"")) | E6: =LOWER(IFERROR(VLOOKUP(AVANZA[[#This Row],[ID_Peticion]],CANCELADAS[#All],3,0),"")) | F6: =LOWER(IF(AVANZA[[#This Row],[CEDULA CLIENTE]]<>""," CC: " & COUNTIFS(AVANZA[CEDULA CLIENTE],AVANZA[[#This Row],[CEDULA CLIENTE]]),"")& IF(AVANZA[[#This Row],[Direccion]]<>""," DIR: " & COUNTIFS(AVANZA[Direccion],AVANZA[[#This Row],[Direccion]]),"")) -> dir: 1 | G6: =IFERROR(VLOOKUP(AVANZA[[#This Row],[Cedula_Vendedor_Atis]],PLANTA[[#All],[CEDULA]:[LINEA]],3,0),"No Cruza") -> Marisol Avella | H6: =IFERROR(VLOOKUP(AVANZA[[#This Row],[Cedula_Vendedor_Atis]],PLANTA[[#All],[CEDULA]:[LINEA]],4,0),"No Cruza") -> Fija | I6: =LOWER(IF(AVANZA[[#This Row],[ATRIBUIBLE]]="",AVANZA[[#This Row],[Variable]],AVANZA[[#This Row],[ATRIBUIBLE]])) -> terminada | J6: =IF(AVANZA[[#This Row],[Variable]]=AVANZA[[#Headers],[TERMINADA]],1,0) -> 1 | K6: =IF(AVANZA[[#This Row],[Variable]]=AVANZA[[#Headers],[ANULADA]],1,0) -> 0 | L6: =IF(AVANZA[[#This Row],[Variable]]=AVANZA[[#Headers],[PENDIENTE]],1,0) -> 0 | M6: =IF(AVANZA[[#This Row],[ESTADO AGENDA]]="AGENDADA",1,0) -> 0 | N6: =IF(AVANZA[[#This Row],[ESTADO AGENDA]]="PENDIENTE DE AGENDAR",1,0) -> 0 | O6: =IF(AVANZA[[#This Row],[ESTADO AGENDA]]="SUSPENDIDA",1,0) -> 0 | P6: {=_xlfn.XLOOKUP(AVANZA[[#This Row],[Num_Agrupacion_Pet_Atis]],Tabla1[[#All],[Numero_de_actuacion]],Tabla1[[#All],[Estado_de_la_orden]],"",0)} | Q6: {=_xlfn.XLOOKUP(AVANZA[[#This Row],[Num_Agrupacion_Pet_Atis]],Tabla1[[#All],[Numero_de_actuacion]],Tabla1[[#All],[Fecha_de_la_cita]],"",0)} | R6: {=_xlfn.XLOOKUP(AVANZA[[#This Row],[Num_Agrupacion_Pet_Atis]],Tabla1[[#All],[Numero_de_actuacion]],Tabla1[[#All],[Franja_horaria_de_la_cita]],"",0)} | S6: =IFERROR(DAY(AVANZA[[#This Row],[FECHA AGENDA]]),"") | T6: =IFERROR(MONTH(AVANZA[[#This Row],[FECHA AGENDA]]),"") | U6: {=_xlfn.XLOOKUP(AVANZA[[#This Row],[Num_Agrupacion_Pet_Atis]],Tabla1[[#All],[Numero_de_actuacion]],Tabla1[[#All],[Motivo_de_suspension]],"",0)} | V6: {=_xlfn.XLOOKUP(AVANZA[[#This Row],[Num_Agrupacion_Pet_Atis]],Tabla1[[#All],[Numero_de_actuacion]],Tabla1[[#All],[No_identificacion_cliente]],"",0)} | W6: {=_xlfn.XLOOKUP(AVANZA[[#This Row],[Num_Agrupacion_Pet_Atis]],Tabla1[[#All],[Numero_de_actuacion]],Tabla1[[#All],[Movil_de_contacto]],"",0)} | X6: =IF(OR(AVANZA[[#This Row],[ESTADO LEG]]="Legalizada grabacion",AVANZA[[#This Row],[ESTADO LEG]]="Legalizada aut"),1,0) -> 1 | Y6: =IF(OR(AVANZA[[#This Row],[ESTADO LEG]]="pdte legalizar",AVANZA[[#This Row],[ESTADO LEG]]="No cruza"),1,0) -> 0 | Z6: {=IF(AVANZA[[#This Row],[Variable]]="Terminada",LOWER(_xlfn.XLOOKUP(AVANZA[[#This Row],[ID_Peticion]],Tabla6[[#All],[NUM_PETICION]],Tabla6[[#All],[ESTADO_LEG]],"NO CRUZA",0)),AVANZA[[#This Row],[Variable]])} -> legalizada grabacion | AA6: {=_xlfn.XLOOKUP(AVANZA[[#This Row],[ID_Peticion]],Tabla6[[#All],[NUM_PETICION]],Tabla6[[#All],[DIF_DIAS]],"",0)} -> 4 | AB6: {=IFERROR(_xlfn.XLOOKUP(AVANZA[[#This Row],[ID_Peticion]],Tabla6[[#All],[NUM_PETICION]],Tabla6[[#All],[FEC_LEGAL]],"",0),"")} -> 46147 | AC6: =IF(AVANZA[[#This Row],[FECHA LEG]]<>0,IFERROR(AVANZA[[#This Row],[FECHA LEG]]-AVANZA[[#This Row],[FechaIniEstadoSubPetAtis]],0),TODAY()-AVANZA[[#This Row],[FechaIniEstadoSubPetAtis]]) -> 4 | AD6: =IF(AVANZA[[#This Row],[FINAL Vs LG]]<>0,IF(AVANZA[[#This Row],[FINAL Vs LG]]<7.1,"100%",IF(AND(AVANZA[[#This Row],[FINAL Vs LG]]>7.1,AVANZA[[#This Row],[FINAL Vs LG]]<11.1),"50%","0%")),0) -> 100% | AE6: =VLOOKUP(DAY(TODAY()),BACK!F:G,2,0) -> 14 | AF6: =BACK!$I$2 -> 24 | AG6: =IF(AVANZA[[#This Row],[Oferta_empaquetada_comisiones]]="SI",1,0) -> 0 | AH6: =IF(AVANZA[[#This Row],[Variable]]="TERMINADA",IFERROR(VLOOKUP(AVANZA[[#This Row],[SUPERVISOR]],Tabla2[#All],4,0),0),) -> 3.5 | AI6: =IF(AVANZA[[#This Row],[Producto]]="BA",1,0) -> 0 | AJ6: =IF(AVANZA[[#This Row],[Producto]]="DUO",1,0) -> 0 | AK6: =IF(AVANZA[[#This Row],[Producto]]="TRIO",1,0) -> 1 | AL6: 53061857 | AM6: -1 | AN6: -1 | AO6: 1784753901 | AP6: 46141.485 | AQ6: -1 | AR6: 2512686193 | AS6: -1 | AT6: -1 | AU6: -1 | AV6: -1 | AW6: -1 | AX6: FixedCreateSubscriber | AY6: -1 | AZ6: 2026 | BA6: 5 | BB6: 1 | BC6: -1 | BD6: Broadband Service | BE6: -1 | BF6: 20001619901767 | BG6: Convergente_Plan Ancha 900Mbps_Mov Ilim_Trio_25422 | BH6: 25422 | BI6: FS202604291136541249 | BJ6: -1 | BK6: -1 | BL6: -1 | BM6: TERMINADA | BN6: Individual | BO6: 6082911402 | BP6: Movistar Total | BQ6: 2026 | BR6: 4 | BS6: 29 | BT6: 46143.555 | BU6: OS90 | BV6: 46143 | BW6: Completed | BX6: 46141 | BY6: 46143 | BZ6: Call Back To CRM | CA6: TURBACO | CB6: BOLIVAR | CC6: KR 32 CL 26-63 EL VALLE 63 APT 1 LAT:10.33987058 LON:-75.42307505 | CD6: EL VALLE | CE6: -1 | CF6: 13836000 | CG6: Bolivar - San Andres | CH6: ATACANTE | CI6: 53061857 | CJ6: NOHORA AMADO LONDONO | CK6: CANAL ONLINE | CL6: ON LINE | CM6: ATENTO COLOMBIA S.A. | CN6: CANAL ON LINE - ATENTO CLICK TO CALL | CT6: 3 | CU6: BA + LB + IPTV | CW6: MTotal_Trio_Voz Ilim Nal _Ba Ancha 900Mbps_IPTV_2_Decos_Mov Ilim_Nac_25425 | CX6: 25425 | DA6: SV | DB6: -1 | DF6: ALTA | DJ6: 900000 | DK6: Cliente Nuevo | DL6: Cliente Nuevo | DN6: TRIO | DR6: namadolo | DS6: NOHORA AMADO LONDONO | DT6: 53061857 | DV6: 1 | DW6: CARIBE | ED6: 46143 | EF6: 20 | EP6: 830065842-5 | ES6: Recreo | FA6: CANAL ONLINE | FB6: Bolívar | FD6: Bolívar | FE6: Turbaco | FF6: Turbaco | FK6: ATENTO | FL6: 13836000OH_BOLALTACO_I_7360_Turbaco_CentroCENTR-CT5-22-02SS5-22-02@13836000_OH_BOLALTACO_I_7360_Turbaco_Centro_CENTR-CT5-22-02_SS5-22-02 | FN6: CANAL ON LINE - ATENTO CLICK TO CALL | FO6: 9900202020033 | FR6: 113904 | GB6: PON | GC6: BA + LB + IPTV | GD6: 25188 | GF6: 2353 | GG6: 25422 | GI6: 87224 | GJ6: 25427 | GL6: 24327 | GM6: 135545 | GS6: FS | GT6: 45382 | GU6: CENTRO EXP | GV6: SIN EMAIL | GW6: Si | GX6: Convergente Solo Contrato | GY6: Convergente Solo Contrato | GZ6: Convergente Existente | HA6: ONNET | HB6: BOLIVAR (CARTAGENA/TURBACO) | HC6: TURBACO | HD6: CARIBE | HE6: Individual | HF6: 1033575420 | HG6: Venta Hogar (F) a cliente Movistar Total | HR6: Asistido | HV6: 118900 | HW6: SI | HX6: Migracion Pos-Pos | HY6: 131572 | HZ6: 17668 | IA6: SI | IB6: NO | ID6: >= 120 | IE6: BOGOTA | IF6: BOGOTA | IG6: BOGOTA | IH6: Digital | II6: Fibra | IJ6: B2C | IK6: Asistido | IL6: C2C | IM6: Atento | IN6: Alta | IP6: - | IQ6: Digital | IS6: ELECTRONICA | IY6: NO
A7: =DAY(AVANZA[[#This Row],[FechaSeguimiento]]) -> 1 | B7: =MONTH(AVANZA[[#This Row],[FechaSeguimiento]]) -> 5 | C7: =LOWER(IF(AND(AVANZA[[#This Row],[Mes_Reg]]=MONTH(TODAY()),AND(AVANZA[[#This Row],[Dia_Reg]]>0,AVANZA[[#This Row],[Dia_Reg]]<9)),"SEMANA 1","")&IF(AND(AVANZA[[#This Row],[Mes_Reg]]=MONTH(TODAY()),AND(AVANZA[[#This Row],[Dia_Reg]]>8,AVANZA[[#This Row],[Dia_Reg]]<16)),"SEMANA 2","")&IF(AND(AVANZA[[#This Row],[Mes_Reg]]=MONTH(TODAY()),AND(AVANZA[[#This Row],[Dia_Reg]]>15,AVANZA[[#This Row],[Dia_Reg]]<23)),"SEMANA 3","")&IF(AND(AVANZA[[#This Row],[Mes_Reg]]=MONTH(TODAY()),AND(AVANZA[[#This Row],[Dia_Reg]]>22,AVANZA[[#This Row],[Dia_Reg]]<31)),"SEMANA 4","")&IF(AVANZA[[#This Row],[Mes_Reg]]<>MONTH(TODAY()),"BOLSA MES ANTERIOR","")) -> bolsa mes anterior | D7: =LOWER(IFERROR(VLOOKUP(AVANZA[[#This Row],[ID_Peticion]],CANCELADAS[#All],2,0),"")) | E7: =LOWER(IFERROR(VLOOKUP(AVANZA[[#This Row],[ID_Peticion]],CANCELADAS[#All],3,0),"")) | F7: =LOWER(IF(AVANZA[[#This Row],[CEDULA CLIENTE]]<>""," CC: " & COUNTIFS(AVANZA[CEDULA CLIENTE],AVANZA[[#This Row],[CEDULA CLIENTE]]),"")& IF(AVANZA[[#This Row],[Direccion]]<>""," DIR: " & COUNTIFS(AVANZA[Direccion],AVANZA[[#This Row],[Direccion]]),"")) -> dir: 1 | G7: =IFERROR(VLOOKUP(AVANZA[[#This Row],[Cedula_Vendedor_Atis]],PLANTA[[#All],[CEDULA]:[LINEA]],3,0),"No Cruza") -> Marisol Avella | H7: =IFERROR(VLOOKUP(AVANZA[[#This Row],[Cedula_Vendedor_Atis]],PLANTA[[#All],[CEDULA]:[LINEA]],4,0),"No Cruza") -> Fija | I7: =LOWER(IF(AVANZA[[#This Row],[ATRIBUIBLE]]="",AVANZA[[#This Row],[Variable]],AVANZA[[#This Row],[ATRIBUIBLE]])) -> terminada | J7: =IF(AVANZA[[#This Row],[Variable]]=AVANZA[[#Headers],[TERMINADA]],1,0) -> 1 | K7: =IF(AVANZA[[#This Row],[Variable]]=AVANZA[[#Headers],[ANULADA]],1,0) -> 0 | L7: =IF(AVANZA[[#This Row],[Variable]]=AVANZA[[#Headers],[PENDIENTE]],1,0) -> 0 | M7: =IF(AVANZA[[#This Row],[ESTADO AGENDA]]="AGENDADA",1,0) -> 0 | N7: =IF(AVANZA[[#This Row],[ESTADO AGENDA]]="PENDIENTE DE AGENDAR",1,0) -> 0 | O7: =IF(AVANZA[[#This Row],[ESTADO AGENDA]]="SUSPENDIDA",1,0) -> 0 | P7: {=_xlfn.XLOOKUP(AVANZA[[#This Row],[Num_Agrupacion_Pet_Atis]],Tabla1[[#All],[Numero_de_actuacion]],Tabla1[[#All],[Estado_de_la_orden]],"",0)} | Q7: {=_xlfn.XLOOKUP(AVANZA[[#This Row],[Num_Agrupacion_Pet_Atis]],Tabla1[[#All],[Numero_de_actuacion]],Tabla1[[#All],[Fecha_de_la_cita]],"",0)} | R7: {=_xlfn.XLOOKUP(AVANZA[[#This Row],[Num_Agrupacion_Pet_Atis]],Tabla1[[#All],[Numero_de_actuacion]],Tabla1[[#All],[Franja_horaria_de_la_cita]],"",0)} | S7: =IFERROR(DAY(AVANZA[[#This Row],[FECHA AGENDA]]),"") | T7: =IFERROR(MONTH(AVANZA[[#This Row],[FECHA AGENDA]]),"") | U7: {=_xlfn.XLOOKUP(AVANZA[[#This Row],[Num_Agrupacion_Pet_Atis]],Tabla1[[#All],[Numero_de_actuacion]],Tabla1[[#All],[Motivo_de_suspension]],"",0)} | V7: {=_xlfn.XLOOKUP(AVANZA[[#This Row],[Num_Agrupacion_Pet_Atis]],Tabla1[[#All],[Numero_de_actuacion]],Tabla1[[#All],[No_identificacion_cliente]],"",0)} | W7: {=_xlfn.XLOOKUP(AVANZA[[#This Row],[Num_Agrupacion_Pet_Atis]],Tabla1[[#All],[Numero_de_actuacion]],Tabla1[[#All],[Movil_de_contacto]],"",0)} | X7: =IF(OR(AVANZA[[#This Row],[ESTADO LEG]]="Legalizada grabacion",AVANZA[[#This Row],[ESTADO LEG]]="Legalizada aut"),1,0) -> 1 | Y7: =IF(OR(AVANZA[[#This Row],[ESTADO LEG]]="pdte legalizar",AVANZA[[#This Row],[ESTADO LEG]]="No cruza"),1,0) -> 0 | Z7: {=IF(AVANZA[[#This Row],[Variable]]="Terminada",LOWER(_xlfn.XLOOKUP(AVANZA[[#This Row],[ID_Peticion]],Tabla6[[#All],[NUM_PETICION]],Tabla6[[#All],[ESTADO_LEG]],"NO CRUZA",0)),AVANZA[[#This Row],[Variable]])} -> legalizada grabacion | AA7: {=_xlfn.XLOOKUP(AVANZA[[#This Row],[ID_Peticion]],Tabla6[[#All],[NUM_PETICION]],Tabla6[[#All],[DIF_DIAS]],"",0)} -> 4 | AB7: {=IFERROR(_xlfn.XLOOKUP(AVANZA[[#This Row],[ID_Peticion]],Tabla6[[#All],[NUM_PETICION]],Tabla6[[#All],[FEC_LEGAL]],"",0),"")} -> 46147 | AC7: =IF(AVANZA[[#This Row],[FECHA LEG]]<>0,IFERROR(AVANZA[[#This Row],[FECHA LEG]]-AVANZA[[#This Row],[FechaIniEstadoSubPetAtis]],0),TODAY()-AVANZA[[#This Row],[FechaIniEstadoSubPetAtis]]) -> 4 | AD7: =IF(AVANZA[[#This Row],[FINAL Vs LG]]<>0,IF(AVANZA[[#This Row],[FINAL Vs LG]]<7.1,"100%",IF(AND(AVANZA[[#This Row],[FINAL Vs LG]]>7.1,AVANZA[[#This Row],[FINAL Vs LG]]<11.1),"50%","0%")),0) -> 100% | AE7: =VLOOKUP(DAY(TODAY()),BACK!F:G,2,0) -> 14 | AF7: =BACK!$I$2 -> 24 | AG7: =IF(AVANZA[[#This Row],[Oferta_empaquetada_comisiones]]="SI",1,0) -> 1 | AH7: =IF(AVANZA[[#This Row],[Variable]]="TERMINADA",IFERROR(VLOOKUP(AVANZA[[#This Row],[SUPERVISOR]],Tabla2[#All],4,0),0),) -> 3.5 | AI7: =IF(AVANZA[[#This Row],[Producto]]="BA",1,0) -> 0 | AJ7: =IF(AVANZA[[#This Row],[Producto]]="DUO",1,0) -> 0 | AK7: =IF(AVANZA[[#This Row],[Producto]]="TRIO",1,0) -> 1 | AL7: 1015443152 | AM7: -1 | AN7: -1 | AO7: 1784429146 | AP7: 46140.794 | AQ7: -1 | AR7: 2512685291 | AS7: -1 | AT7: -1 | AU7: -1 | AV7: -1 | AW7: -1 | AX7: FixedCreateSubscriber | AY7: -1 | AZ7: 2026 | BA7: 5 | BB7: 1 | BC7: -1 | BD7: Broadband Service | BE7: -1 | BF7: 20001619646227 | BG7: Convergente_Plan Ancha 900Mbps_Mov Ilim_Trio_25422 | BH7: 25422 | BI7: FS202604281902281085 | BJ7: -1 | BK7: -1 | BL7: -1 | BM7: TERMINADA | BN7: Individual | BO7: 6108727678 | BP7: Movistar Total | BQ7: 2026 | BR7: 4 | BS7: 28 | BT7: 46143.559 | BU7: OS90 | BV7: 46143 | BW7: Completed | BX7: 46140 | BY7: 46143 | BZ7: Call Back To CRM | CA7: BOGOTA, D.C. | CB7: BOGOTA, D.C. | CC7: CL 35 B S KR 73 B-23 SUPER MANZANA 3 23 APT 201 LAT:4.62043741 LON:-74.14649193 | CD7: SUPER MANZANA 3 | CE7: -1 | CF7: 11001000 | CG7: Bogota | CH7: ATACANTE | CI7: 1015443152 | CJ7: BRAYAN NICOLAS SIERRA RODRIGUEZ | CK7: CANAL ONLINE | CL7: TELEVENTAS | CM7: ATENTO COLOMBIA S.A. | CN7: CANAL ON LINE - ATENTO OUT BOUND | CT7: 3 | CU7: BA + LB + IPTV | CW7: MTotal_Trio_Voz Ilim Nal _Ba Ancha 900Mbps_IPTV_2_Decos_Mov Ilim_Nac_25425 | CX7: 25425 | DA7: SV | DB7: -1 | DF7: ALTA | DJ7: 900000 | DK7: Cliente Nuevo | DL7: Cliente Nuevo | DN7: TRIO | DR7: bnsierraro | DS7: BRAYAN NICOLAS SIERRA RODRIGUEZ | DT7: 1015443152 | DV7: 1 | DW7: BOGOTA | ED7: 46143 | EE7: Sur | EF7: 5 | EP7: 830065842-5 | ES7: 63 | EZ7: OLT#10.37.80.14 | FA7: CANAL ONLINE | FB7: Bogotá D.C | FD7: Bogotá D.C | FE7: Bogotá | FF7: Bogotá | FK7: ATENTO | FL7: 11001000158059110656999|11001000_158059110_CT6/7-32-20 | FN7: CANAL ON LINE - ATENTO OUT BOUND | FO7: 9900202020034 | FR7: 113904 | GB7: PON | GC7: BA + LB + IPTV | GD7: 25188 | GF7: 2353 | GG7: 25422 | GI7: 87224 | GJ7: 25427 | GL7: 24327 | GM7: 135545 | GS7: FS | GT7: 45716 | GU7: CENTRO EXP | GW7: Si | GX7: SV | GY7: Convergente Solo Contrato | GZ7: Convergente Nuevo | HA7: ATP | HC7: BOGOTA | HE7: Individual | HF7: 462074145 | HG7: Venta mismo mes (F+M) diferente Canal_diferente Al | HH7: 52976181 | HI7: 1. Radicadas | HJ7: 46145 | HK7: CENTROS DE EXPERIENCIA | HL7: CENTROS DE EXPERIENCIA | HM7: 9900100010031 | HN7: CE BOGOTA PLAZA DE LAS AMERICAS | HO7: JHON FREDY PARADA ALVAREZ | HP7: 1032368879 | HR7: Asistido | HV7: 118900 | HW7: SI | HX7: Radicada - No nato igual a NO | HY7: 131572 | HZ7: 17668 | IA7: SI | IB7: NO | IE7: BOGOTA | IF7: BOGOTA | IG7: BOGOTA | IH7: Digital | II7: Fibra | IJ7: B2C | IK7: Asistido | IL7: Outbound | IM7: Atento | IN7: Alta | IP7: - | IQ7: Digital | IS7: ELECTRONICA | IT7: Inbound | IY7: SI
A8: =DAY(AVANZA[[#This Row],[FechaSeguimiento]]) -> 1 | B8: =MONTH(AVANZA[[#This Row],[FechaSeguimiento]]) -> 5 | C8: =LOWER(IF(AND(AVANZA[[#This Row],[Mes_Reg]]=MONTH(TODAY()),AND(AVANZA[[#This Row],[Dia_Reg]]>0,AVANZA[[#This Row],[Dia_Reg]]<9)),"SEMANA 1","")&IF(AND(AVANZA[[#This Row],[Mes_Reg]]=MONTH(TODAY()),AND(AVANZA[[#This Row],[Dia_Reg]]>8,AVANZA[[#This Row],[Dia_Reg]]<16)),"SEMANA 2","")&IF(AND(AVANZA[[#This Row],[Mes_Reg]]=MONTH(TODAY()),AND(AVANZA[[#This Row],[Dia_Reg]]>15,AVANZA[[#This Row],[Dia_Reg]]<23)),"SEMANA 3","")&IF(AND(AVANZA[[#This Row],[Mes_Reg]]=MONTH(TODAY()),AND(AVANZA[[#This Row],[Dia_Reg]]>22,AVANZA[[#This Row],[Dia_Reg]]<31)),"SEMANA 4","")&IF(AVANZA[[#This Row],[Mes_Reg]]<>MONTH(TODAY()),"BOLSA MES ANTERIOR","")) -> bolsa mes anterior | D8: =LOWER(IFERROR(VLOOKUP(AVANZA[[#This Row],[ID_Peticion]],CANCELADAS[#All],2,0),"")) -> carrusel | E8: =LOWER(IFERROR(VLOOKUP(AVANZA[[#This Row],[ID_Peticion]],CANCELADAS[#All],3,0),"")) -> carrusel | F8: =LOWER(IF(AVANZA[[#This Row],[CEDULA CLIENTE]]<>""," CC: " & COUNTIFS(AVANZA[CEDULA CLIENTE],AVANZA[[#This Row],[CEDULA CLIENTE]]),"")& IF(AVANZA[[#This Row],[Direccion]]<>""," DIR: " & COUNTIFS(AVANZA[Direccion],AVANZA[[#This Row],[Direccion]]),"")) -> dir: 1 | G8: =IFERROR(VLOOKUP(AVANZA[[#This Row],[Cedula_Vendedor_Atis]],PLANTA[[#All],[CEDULA]:[LINEA]],3,0),"No Cruza") -> Marisol Avella | H8: =IFERROR(VLOOKUP(AVANZA[[#This Row],[Cedula_Vendedor_Atis]],PLANTA[[#All],[CEDULA]:[LINEA]],4,0),"No Cruza") -> Fija | I8: =LOWER(IF(AVANZA[[#This Row],[ATRIBUIBLE]]="",AVANZA[[#This Row],[Variable]],AVANZA[[#This Row],[ATRIBUIBLE]])) -> carrusel | J8: =IF(AVANZA[[#This Row],[Variable]]=AVANZA[[#Headers],[TERMINADA]],1,0) -> 0 | K8: =IF(AVANZA[[#This Row],[Variable]]=AVANZA[[#Headers],[ANULADA]],1,0) -> 1 | L8: =IF(AVANZA[[#This Row],[Variable]]=AVANZA[[#Headers],[PENDIENTE]],1,0) -> 0 | M8: =IF(AVANZA[[#This Row],[ESTADO AGENDA]]="AGENDADA",1,0) -> 0 | N8: =IF(AVANZA[[#This Row],[ESTADO AGENDA]]="PENDIENTE DE AGENDAR",1,0) -> 0 | O8: =IF(AVANZA[[#This Row],[ESTADO AGENDA]]="SUSPENDIDA",1,0) -> 0 | P8: {=_xlfn.XLOOKUP(AVANZA[[#This Row],[Num_Agrupacion_Pet_Atis]],Tabla1[[#All],[Numero_de_actuacion]],Tabla1[[#All],[Estado_de_la_orden]],"",0)} | Q8: {=_xlfn.XLOOKUP(AVANZA[[#This Row],[Num_Agrupacion_Pet_Atis]],Tabla1[[#All],[Numero_de_actuacion]],Tabla1[[#All],[Fecha_de_la_cita]],"",0)} | R8: {=_xlfn.XLOOKUP(AVANZA[[#This Row],[Num_Agrupacion_Pet_Atis]],Tabla1[[#All],[Numero_de_actuacion]],Tabla1[[#All],[Franja_horaria_de_la_cita]],"",0)} | S8: =IFERROR(DAY(AVANZA[[#This Row],[FECHA AGENDA]]),"") | T8: =IFERROR(MONTH(AVANZA[[#This Row],[FECHA AGENDA]]),"") | U8: {=_xlfn.XLOOKUP(AVANZA[[#This Row],[Num_Agrupacion_Pet_Atis]],Tabla1[[#All],[Numero_de_actuacion]],Tabla1[[#All],[Motivo_de_suspension]],"",0)} | V8: {=_xlfn.XLOOKUP(AVANZA[[#This Row],[Num_Agrupacion_Pet_Atis]],Tabla1[[#All],[Numero_de_actuacion]],Tabla1[[#All],[No_identificacion_cliente]],"",0)} | W8: {=_xlfn.XLOOKUP(AVANZA[[#This Row],[Num_Agrupacion_Pet_Atis]],Tabla1[[#All],[Numero_de_actuacion]],Tabla1[[#All],[Movil_de_contacto]],"",0)} | X8: =IF(OR(AVANZA[[#This Row],[ESTADO LEG]]="Legalizada grabacion",AVANZA[[#This Row],[ESTADO LEG]]="Legalizada aut"),1,0) -> 0 | Y8: =IF(OR(AVANZA[[#This Row],[ESTADO LEG]]="pdte legalizar",AVANZA[[#This Row],[ESTADO LEG]]="No cruza"),1,0) -> 0 | Z8: {=IF(AVANZA[[#This Row],[Variable]]="Terminada",LOWER(_xlfn.XLOOKUP(AVANZA[[#This Row],[ID_Peticion]],Tabla6[[#All],[NUM_PETICION]],Tabla6[[#All],[ESTADO_LEG]],"NO CRUZA",0)),AVANZA[[#This Row],[Variable]])} -> ANULADA | AA8: {=_xlfn.XLOOKUP(AVANZA[[#This Row],[ID_Peticion]],Tabla6[[#All],[NUM_PETICION]],Tabla6[[#All],[DIF_DIAS]],"",0)} | AB8: {=IFERROR(_xlfn.XLOOKUP(AVANZA[[#This Row],[ID_Peticion]],Tabla6[[#All],[NUM_PETICION]],Tabla6[[#All],[FEC_LEGAL]],"",0),"")} | AC8: =IF(AVANZA[[#This Row],[FECHA LEG]]<>0,IFERROR(AVANZA[[#This Row],[FECHA LEG]]-AVANZA[[#This Row],[FechaIniEstadoSubPetAtis]],0),TODAY()-AVANZA[[#This Row],[FechaIniEstadoSubPetAtis]]) -> 0 | AD8: =IF(AVANZA[[#This Row],[FINAL Vs LG]]<>0,IF(AVANZA[[#This Row],[FINAL Vs LG]]<7.1,"100%",IF(AND(AVANZA[[#This Row],[FINAL Vs LG]]>7.1,AVANZA[[#This Row],[FINAL Vs LG]]<11.1),"50%","0%")),0) -> 0 | AE8: =VLOOKUP(DAY(TODAY()),BACK!F:G,2,0) -> 14 | AF8: =BACK!$I$2 -> 24 | AG8: =IF(AVANZA[[#This Row],[Oferta_empaquetada_comisiones]]="SI",1,0) -> 0 | AH8: =IF(AVANZA[[#This Row],[Variable]]="TERMINADA",IFERROR(VLOOKUP(AVANZA[[#This Row],[SUPERVISOR]],Tabla2[#All],4,0),0),) -> 0 | AI8: =IF(AVANZA[[#This Row],[Producto]]="BA",1,0) -> 0 | AJ8: =IF(AVANZA[[#This Row],[Producto]]="DUO",1,0) -> 0 | AK8: =IF(AVANZA[[#This Row],[Producto]]="TRIO",1,0) -> 1 | AL8: 53061857 | AM8: -1 | AN8: -1 | AO8: 1785741102 | AP8: 46142.678 | AQ8: -1 | AR8: 2512690158 | AS8: -1 | AT8: -1 | AU8: -1 | AV8: -1 | AW8: -1 | AX8: FixedCreateSubscriber | AY8: -1 | AZ8: 2026 | BA8: 5 | BB8: 1 | BC8: -1 | BD8: Broadband Service | BE8: -1 | BF8: 20001620825343 | BG8: Convergente_Plan Ancha 900Mbps_Mov Ilim_Trio_25422 | BH8: 25422 | BJ8: -1 | BK8: -1 | BL8: -1 | BM8: ANULADA | BN8: Individual | BO8: 6108770235 | BP8: Gold | BQ8: 2026 | BR8: 4 | BS8: 30 | BT8: 46143.414 | BU8: OS80 | BV8: 46143 | BW8: Cancelled | CA8: DISTRITO ESPECIAL, INDUSTRIAL Y PORTUARIO DE BARRANQUILLA | CB8: ATLANTICO | CC8: KR 8 F CL 130-33 URB CIUDAD CARIBE 33 LAT:10.953894 LON:-74.85522699 | CD8: URB CIUDAD CARIBE | CE8: -1 | CF8: 08001000 | CG8: Atlantico | CH8: ATACANTE | CI8: 53061857 | CJ8: NOHORA AMADO LONDONO | CK8: CANAL ONLINE | CL8: ON LINE | CM8: ATENTO COLOMBIA S.A. | CN8: CANAL ON LINE - ATENTO CLICK TO CALL | CT8: 1 | CU8: BA + LB + IPTV | CW8: MTotal_Trio_Voz Ilim Nal _Ba Ancha 900Mbps_IPTV_2_Decos_Mov Ilim_Nac_25425 | CX8: 25425 | CY8: Anulada fraude marcada por campo remark | DA8: SV | DB8: -1 | DF8: ANULADA FRAUDE - REMARK | DJ8: 900000 | DK8: Cliente Nuevo | DL8: Cliente Nuevo | DN8: TRIO | DR8: namadolo | DS8: NOHORA AMADO LONDONO | DT8: 53061857 | DV8: 1 | DW8: CARIBE | ED8: 46143 | EF8: 9 | EP8: 830065842-5 | FA8: CANAL ONLINE | FB8: Atlántico | FD8: Atlántico | FE8: Barranquilla | FF8: Distrito Especial, Industrial Y Portuario De Barranquilla | FK8: ATENTO | FN8: CANAL ON LINE - ATENTO CLICK TO CALL | FO8: 9900202020033 | FR8: 0 | GB8: PON | GM8: 0 | GS8: FS | GU8: CENTRO EXP | GV8: VALIDADO | GW8: No | GZ8: No Convergente | HE8: Individual | HF8: 1095074855 | HR8: Asistido | HV8: 118900 | HW8: SI | HY8: 0 | HZ8: 0 | IA8: SI | IB8: NO | IC8: The Fraud order (Carrusel) is cancelled by SOM. | IE8: BOGOTA | IF8: BOGOTA | IG8: BOGOTA | IH8: Digital | II8: Fibra | IJ8: B2C | IK8: Asistido | IL8: C2C | IM8: Atento | IN8: - | IP8: - | IQ8: Digital | IS8: ELECTRONICA | IT8: Organico | IW8: Fibra-Fibra-web-CajadeProducto-LP_Hogar_Trio | IY8: NO
